[2025-05-12 23:42:31,404] {taskinstance.py:1159} INFO - Dependencies all met for <TaskInstance: api_pipeline_integration.trigger_and_wait_pipeline scheduled__2025-05-12T23:30:00+00:00 [queued]>
[2025-05-12 23:42:31,410] {taskinstance.py:1159} INFO - Dependencies all met for <TaskInstance: api_pipeline_integration.trigger_and_wait_pipeline scheduled__2025-05-12T23:30:00+00:00 [queued]>
[2025-05-12 23:42:31,410] {taskinstance.py:1356} INFO - 
--------------------------------------------------------------------------------
[2025-05-12 23:42:31,410] {taskinstance.py:1357} INFO - Starting attempt 2 of 4
[2025-05-12 23:42:31,410] {taskinstance.py:1358} INFO - 
--------------------------------------------------------------------------------
[2025-05-12 23:42:31,417] {taskinstance.py:1377} INFO - Executing <Task(PythonOperator): trigger_and_wait_pipeline> on 2025-05-12 23:30:00+00:00
[2025-05-12 23:42:31,420] {standard_task_runner.py:52} INFO - Started process 273 to run task
[2025-05-12 23:42:31,422] {standard_task_runner.py:79} INFO - Running: ['***', 'tasks', 'run', 'api_pipeline_integration', 'trigger_and_wait_pipeline', 'scheduled__2025-05-12T23:30:00+00:00', '--job-id', '5', '--raw', '--subdir', 'DAGS_FOLDER/extract_scheduler.py', '--cfg-path', '/tmp/tmpxk_8y9pw', '--error-file', '/tmp/tmpknxz757l']
[2025-05-12 23:42:31,423] {standard_task_runner.py:80} INFO - Job 5: Subtask trigger_and_wait_pipeline
[2025-05-12 23:42:31,463] {task_command.py:369} INFO - Running <TaskInstance: api_pipeline_integration.trigger_and_wait_pipeline scheduled__2025-05-12T23:30:00+00:00 [running]> on host f4c955ecac73
[2025-05-12 23:42:31,508] {taskinstance.py:1571} INFO - Exporting the following env vars:
AIRFLOW_CTX_DAG_OWNER=***
AIRFLOW_CTX_DAG_ID=api_pipeline_integration
AIRFLOW_CTX_TASK_ID=trigger_and_wait_pipeline
AIRFLOW_CTX_EXECUTION_DATE=2025-05-12T23:30:00+00:00
AIRFLOW_CTX_TRY_NUMBER=2
AIRFLOW_CTX_DAG_RUN_ID=scheduled__2025-05-12T23:30:00+00:00
[2025-05-12 23:43:01,609] {taskinstance.py:1889} ERROR - Task failed with exception
Traceback (most recent call last):
  File "/home/airflow/.local/lib/python3.7/site-packages/urllib3/connection.py", line 175, in _new_conn
    (self._dns_host, self.port), self.timeout, **extra_kw
  File "/home/airflow/.local/lib/python3.7/site-packages/urllib3/util/connection.py", line 95, in create_connection
    raise err
  File "/home/airflow/.local/lib/python3.7/site-packages/urllib3/util/connection.py", line 85, in create_connection
    sock.connect(sa)
socket.timeout: timed out

During handling of the above exception, another exception occurred:

Traceback (most recent call last):
  File "/home/airflow/.local/lib/python3.7/site-packages/urllib3/connectionpool.py", line 710, in urlopen
    chunked=chunked,
  File "/home/airflow/.local/lib/python3.7/site-packages/urllib3/connectionpool.py", line 398, in _make_request
    conn.request(method, url, **httplib_request_kw)
  File "/home/airflow/.local/lib/python3.7/site-packages/urllib3/connection.py", line 239, in request
    super(HTTPConnection, self).request(method, url, body=body, headers=headers)
  File "/usr/local/lib/python3.7/http/client.py", line 1281, in request
    self._send_request(method, url, body, headers, encode_chunked)
  File "/usr/local/lib/python3.7/http/client.py", line 1327, in _send_request
    self.endheaders(body, encode_chunked=encode_chunked)
  File "/usr/local/lib/python3.7/http/client.py", line 1276, in endheaders
    self._send_output(message_body, encode_chunked=encode_chunked)
  File "/usr/local/lib/python3.7/http/client.py", line 1036, in _send_output
    self.send(msg)
  File "/usr/local/lib/python3.7/http/client.py", line 976, in send
    self.connect()
  File "/home/airflow/.local/lib/python3.7/site-packages/urllib3/connection.py", line 205, in connect
    conn = self._new_conn()
  File "/home/airflow/.local/lib/python3.7/site-packages/urllib3/connection.py", line 182, in _new_conn
    % (self.host, self.timeout),
urllib3.exceptions.ConnectTimeoutError: (<urllib3.connection.HTTPConnection object at 0x7999280fa390>, 'Connection to host.docker.internal timed out. (connect timeout=30)')

During handling of the above exception, another exception occurred:

Traceback (most recent call last):
  File "/home/airflow/.local/lib/python3.7/site-packages/requests/adapters.py", line 450, in send
    timeout=timeout
  File "/home/airflow/.local/lib/python3.7/site-packages/urllib3/connectionpool.py", line 786, in urlopen
    method, url, error=e, _pool=self, _stacktrace=sys.exc_info()[2]
  File "/home/airflow/.local/lib/python3.7/site-packages/urllib3/util/retry.py", line 592, in increment
    raise MaxRetryError(_pool, url, error or ResponseError(cause))
urllib3.exceptions.MaxRetryError: HTTPConnectionPool(host='host.docker.internal', port=8000): Max retries exceeded with url: /run-pipeline (Caused by ConnectTimeoutError(<urllib3.connection.HTTPConnection object at 0x7999280fa390>, 'Connection to host.docker.internal timed out. (connect timeout=30)'))

During handling of the above exception, another exception occurred:

Traceback (most recent call last):
  File "/opt/airflow/dags/extract_scheduler.py", line 21, in trigger_pipeline
    response = requests.post(api_url, timeout=30)
  File "/home/airflow/.local/lib/python3.7/site-packages/requests/api.py", line 117, in post
    return request('post', url, data=data, json=json, **kwargs)
  File "/home/airflow/.local/lib/python3.7/site-packages/requests/api.py", line 61, in request
    return session.request(method=method, url=url, **kwargs)
  File "/home/airflow/.local/lib/python3.7/site-packages/requests/sessions.py", line 529, in request
    resp = self.send(prep, **send_kwargs)
  File "/home/airflow/.local/lib/python3.7/site-packages/requests/sessions.py", line 645, in send
    r = adapter.send(request, **kwargs)
  File "/home/airflow/.local/lib/python3.7/site-packages/requests/adapters.py", line 507, in send
    raise ConnectTimeout(e, request=request)
requests.exceptions.ConnectTimeout: HTTPConnectionPool(host='host.docker.internal', port=8000): Max retries exceeded with url: /run-pipeline (Caused by ConnectTimeoutError(<urllib3.connection.HTTPConnection object at 0x7999280fa390>, 'Connection to host.docker.internal timed out. (connect timeout=30)'))

During handling of the above exception, another exception occurred:

Traceback (most recent call last):
  File "/home/airflow/.local/lib/python3.7/site-packages/airflow/operators/python.py", line 171, in execute
    return_value = self.execute_callable()
  File "/home/airflow/.local/lib/python3.7/site-packages/airflow/operators/python.py", line 189, in execute_callable
    return self.python_callable(*self.op_args, **self.op_kwargs)
  File "/opt/airflow/dags/extract_scheduler.py", line 45, in trigger_pipeline
    raise Exception(f"API connection error: {str(e)}")
Exception: API connection error: HTTPConnectionPool(host='host.docker.internal', port=8000): Max retries exceeded with url: /run-pipeline (Caused by ConnectTimeoutError(<urllib3.connection.HTTPConnection object at 0x7999280fa390>, 'Connection to host.docker.internal timed out. (connect timeout=30)'))
[2025-05-12 23:43:01,625] {taskinstance.py:1400} INFO - Marking task as UP_FOR_RETRY. dag_id=api_pipeline_integration, task_id=trigger_and_wait_pipeline, execution_date=20250512T233000, start_date=20250512T234231, end_date=20250512T234301
[2025-05-12 23:43:01,639] {standard_task_runner.py:97} ERROR - Failed to execute job 5 for task trigger_and_wait_pipeline (API connection error: HTTPConnectionPool(host='host.docker.internal', port=8000): Max retries exceeded with url: /run-pipeline (Caused by ConnectTimeoutError(<urllib3.connection.HTTPConnection object at 0x7999280fa390>, 'Connection to host.docker.internal timed out. (connect timeout=30)')); 273)
[2025-05-12 23:43:01,685] {local_task_job.py:156} INFO - Task exited with return code 1
[2025-05-12 23:43:01,714] {local_task_job.py:273} INFO - 0 downstream tasks scheduled from follow-on schedule check
