[2025-05-12 23:33:13,156] {taskinstance.py:1159} INFO - Dependencies all met for <TaskInstance: api_pipeline_integration.trigger_and_wait_pipeline scheduled__2025-05-12T23:20:00+00:00 [queued]>
[2025-05-12 23:33:13,161] {taskinstance.py:1159} INFO - Dependencies all met for <TaskInstance: api_pipeline_integration.trigger_and_wait_pipeline scheduled__2025-05-12T23:20:00+00:00 [queued]>
[2025-05-12 23:33:13,161] {taskinstance.py:1356} INFO - 
--------------------------------------------------------------------------------
[2025-05-12 23:33:13,161] {taskinstance.py:1357} INFO - Starting attempt 1 of 4
[2025-05-12 23:33:13,161] {taskinstance.py:1358} INFO - 
--------------------------------------------------------------------------------
[2025-05-12 23:33:13,170] {taskinstance.py:1377} INFO - Executing <Task(PythonOperator): trigger_and_wait_pipeline> on 2025-05-12 23:20:00+00:00
[2025-05-12 23:33:13,173] {standard_task_runner.py:52} INFO - Started process 538 to run task
[2025-05-12 23:33:13,175] {standard_task_runner.py:79} INFO - Running: ['***', 'tasks', 'run', 'api_pipeline_integration', 'trigger_and_wait_pipeline', 'scheduled__2025-05-12T23:20:00+00:00', '--job-id', '38', '--raw', '--subdir', 'DAGS_FOLDER/extract_scheduler.py', '--cfg-path', '/tmp/tmp9ffjqlt_', '--error-file', '/tmp/tmplomope8d']
[2025-05-12 23:33:13,176] {standard_task_runner.py:80} INFO - Job 38: Subtask trigger_and_wait_pipeline
[2025-05-12 23:33:13,213] {task_command.py:369} INFO - Running <TaskInstance: api_pipeline_integration.trigger_and_wait_pipeline scheduled__2025-05-12T23:20:00+00:00 [running]> on host 5920a77763c0
[2025-05-12 23:33:13,270] {taskinstance.py:1571} INFO - Exporting the following env vars:
AIRFLOW_CTX_DAG_OWNER=***
AIRFLOW_CTX_DAG_ID=api_pipeline_integration
AIRFLOW_CTX_TASK_ID=trigger_and_wait_pipeline
AIRFLOW_CTX_EXECUTION_DATE=2025-05-12T23:20:00+00:00
AIRFLOW_CTX_TRY_NUMBER=1
AIRFLOW_CTX_DAG_RUN_ID=scheduled__2025-05-12T23:20:00+00:00
[2025-05-12 23:33:13,274] {taskinstance.py:1889} ERROR - Task failed with exception
Traceback (most recent call last):
  File "/home/airflow/.local/lib/python3.7/site-packages/urllib3/connection.py", line 175, in _new_conn
    (self._dns_host, self.port), self.timeout, **extra_kw
  File "/home/airflow/.local/lib/python3.7/site-packages/urllib3/util/connection.py", line 72, in create_connection
    for res in socket.getaddrinfo(host, port, family, socket.SOCK_STREAM):
  File "/usr/local/lib/python3.7/socket.py", line 752, in getaddrinfo
    for res in _socket.getaddrinfo(host, port, family, type, proto, flags):
socket.gaierror: [Errno -3] Temporary failure in name resolution

During handling of the above exception, another exception occurred:

Traceback (most recent call last):
  File "/home/airflow/.local/lib/python3.7/site-packages/urllib3/connectionpool.py", line 710, in urlopen
    chunked=chunked,
  File "/home/airflow/.local/lib/python3.7/site-packages/urllib3/connectionpool.py", line 398, in _make_request
    conn.request(method, url, **httplib_request_kw)
  File "/home/airflow/.local/lib/python3.7/site-packages/urllib3/connection.py", line 239, in request
    super(HTTPConnection, self).request(method, url, body=body, headers=headers)
  File "/usr/local/lib/python3.7/http/client.py", line 1281, in request
    self._send_request(method, url, body, headers, encode_chunked)
  File "/usr/local/lib/python3.7/http/client.py", line 1327, in _send_request
    self.endheaders(body, encode_chunked=encode_chunked)
  File "/usr/local/lib/python3.7/http/client.py", line 1276, in endheaders
    self._send_output(message_body, encode_chunked=encode_chunked)
  File "/usr/local/lib/python3.7/http/client.py", line 1036, in _send_output
    self.send(msg)
  File "/usr/local/lib/python3.7/http/client.py", line 976, in send
    self.connect()
  File "/home/airflow/.local/lib/python3.7/site-packages/urllib3/connection.py", line 205, in connect
    conn = self._new_conn()
  File "/home/airflow/.local/lib/python3.7/site-packages/urllib3/connection.py", line 187, in _new_conn
    self, "Failed to establish a new connection: %s" % e
urllib3.exceptions.NewConnectionError: <urllib3.connection.HTTPConnection object at 0x785a960cb5d0>: Failed to establish a new connection: [Errno -3] Temporary failure in name resolution

During handling of the above exception, another exception occurred:

Traceback (most recent call last):
  File "/home/airflow/.local/lib/python3.7/site-packages/requests/adapters.py", line 450, in send
    timeout=timeout
  File "/home/airflow/.local/lib/python3.7/site-packages/urllib3/connectionpool.py", line 786, in urlopen
    method, url, error=e, _pool=self, _stacktrace=sys.exc_info()[2]
  File "/home/airflow/.local/lib/python3.7/site-packages/urllib3/util/retry.py", line 592, in increment
    raise MaxRetryError(_pool, url, error or ResponseError(cause))
urllib3.exceptions.MaxRetryError: HTTPConnectionPool(host='campground_api', port=8000): Max retries exceeded with url: /run-pipeline (Caused by NewConnectionError('<urllib3.connection.HTTPConnection object at 0x785a960cb5d0>: Failed to establish a new connection: [Errno -3] Temporary failure in name resolution'))

During handling of the above exception, another exception occurred:

Traceback (most recent call last):
  File "/opt/airflow/dags/extract_scheduler.py", line 21, in trigger_pipeline
    response = requests.post(api_url, timeout=30)
  File "/home/airflow/.local/lib/python3.7/site-packages/requests/api.py", line 117, in post
    return request('post', url, data=data, json=json, **kwargs)
  File "/home/airflow/.local/lib/python3.7/site-packages/requests/api.py", line 61, in request
    return session.request(method=method, url=url, **kwargs)
  File "/home/airflow/.local/lib/python3.7/site-packages/requests/sessions.py", line 529, in request
    resp = self.send(prep, **send_kwargs)
  File "/home/airflow/.local/lib/python3.7/site-packages/requests/sessions.py", line 645, in send
    r = adapter.send(request, **kwargs)
  File "/home/airflow/.local/lib/python3.7/site-packages/requests/adapters.py", line 519, in send
    raise ConnectionError(e, request=request)
requests.exceptions.ConnectionError: HTTPConnectionPool(host='campground_api', port=8000): Max retries exceeded with url: /run-pipeline (Caused by NewConnectionError('<urllib3.connection.HTTPConnection object at 0x785a960cb5d0>: Failed to establish a new connection: [Errno -3] Temporary failure in name resolution'))

During handling of the above exception, another exception occurred:

Traceback (most recent call last):
  File "/home/airflow/.local/lib/python3.7/site-packages/airflow/operators/python.py", line 171, in execute
    return_value = self.execute_callable()
  File "/home/airflow/.local/lib/python3.7/site-packages/airflow/operators/python.py", line 189, in execute_callable
    return self.python_callable(*self.op_args, **self.op_kwargs)
  File "/opt/airflow/dags/extract_scheduler.py", line 45, in trigger_pipeline
    raise Exception(f"API connection error: {str(e)}")
Exception: API connection error: HTTPConnectionPool(host='campground_api', port=8000): Max retries exceeded with url: /run-pipeline (Caused by NewConnectionError('<urllib3.connection.HTTPConnection object at 0x785a960cb5d0>: Failed to establish a new connection: [Errno -3] Temporary failure in name resolution'))
[2025-05-12 23:33:13,282] {taskinstance.py:1400} INFO - Marking task as UP_FOR_RETRY. dag_id=api_pipeline_integration, task_id=trigger_and_wait_pipeline, execution_date=20250512T232000, start_date=20250512T233313, end_date=20250512T233313
[2025-05-12 23:33:13,291] {standard_task_runner.py:97} ERROR - Failed to execute job 38 for task trigger_and_wait_pipeline (API connection error: HTTPConnectionPool(host='campground_api', port=8000): Max retries exceeded with url: /run-pipeline (Caused by NewConnectionError('<urllib3.connection.HTTPConnection object at 0x785a960cb5d0>: Failed to establish a new connection: [Errno -3] Temporary failure in name resolution')); 538)
[2025-05-12 23:33:13,306] {local_task_job.py:156} INFO - Task exited with return code 1
[2025-05-12 23:33:13,331] {local_task_job.py:273} INFO - 0 downstream tasks scheduled from follow-on schedule check
[2025-05-12 23:37:12,081] {taskinstance.py:1159} INFO - Dependencies all met for <TaskInstance: api_pipeline_integration.trigger_and_wait_pipeline scheduled__2025-05-12T23:20:00+00:00 [queued]>
[2025-05-12 23:37:12,086] {taskinstance.py:1159} INFO - Dependencies all met for <TaskInstance: api_pipeline_integration.trigger_and_wait_pipeline scheduled__2025-05-12T23:20:00+00:00 [queued]>
[2025-05-12 23:37:12,086] {taskinstance.py:1356} INFO - 
--------------------------------------------------------------------------------
[2025-05-12 23:37:12,086] {taskinstance.py:1357} INFO - Starting attempt 1 of 4
[2025-05-12 23:37:12,086] {taskinstance.py:1358} INFO - 
--------------------------------------------------------------------------------
[2025-05-12 23:37:12,093] {taskinstance.py:1377} INFO - Executing <Task(PythonOperator): trigger_and_wait_pipeline> on 2025-05-12 23:20:00+00:00
[2025-05-12 23:37:12,097] {standard_task_runner.py:52} INFO - Started process 587 to run task
[2025-05-12 23:37:12,099] {standard_task_runner.py:79} INFO - Running: ['***', 'tasks', 'run', 'api_pipeline_integration', 'trigger_and_wait_pipeline', 'scheduled__2025-05-12T23:20:00+00:00', '--job-id', '40', '--raw', '--subdir', 'DAGS_FOLDER/extract_scheduler.py', '--cfg-path', '/tmp/tmpqifemg7r', '--error-file', '/tmp/tmpqc2ldz_4']
[2025-05-12 23:37:12,100] {standard_task_runner.py:80} INFO - Job 40: Subtask trigger_and_wait_pipeline
[2025-05-12 23:37:12,133] {task_command.py:369} INFO - Running <TaskInstance: api_pipeline_integration.trigger_and_wait_pipeline scheduled__2025-05-12T23:20:00+00:00 [running]> on host 5920a77763c0
[2025-05-12 23:37:12,178] {taskinstance.py:1571} INFO - Exporting the following env vars:
AIRFLOW_CTX_DAG_OWNER=***
AIRFLOW_CTX_DAG_ID=api_pipeline_integration
AIRFLOW_CTX_TASK_ID=trigger_and_wait_pipeline
AIRFLOW_CTX_EXECUTION_DATE=2025-05-12T23:20:00+00:00
AIRFLOW_CTX_TRY_NUMBER=1
AIRFLOW_CTX_DAG_RUN_ID=scheduled__2025-05-12T23:20:00+00:00
[2025-05-12 23:37:12,263] {taskinstance.py:1889} ERROR - Task failed with exception
Traceback (most recent call last):
  File "/home/airflow/.local/lib/python3.7/site-packages/urllib3/connection.py", line 175, in _new_conn
    (self._dns_host, self.port), self.timeout, **extra_kw
  File "/home/airflow/.local/lib/python3.7/site-packages/urllib3/util/connection.py", line 95, in create_connection
    raise err
  File "/home/airflow/.local/lib/python3.7/site-packages/urllib3/util/connection.py", line 85, in create_connection
    sock.connect(sa)
ConnectionRefusedError: [Errno 111] Connection refused

During handling of the above exception, another exception occurred:

Traceback (most recent call last):
  File "/home/airflow/.local/lib/python3.7/site-packages/urllib3/connectionpool.py", line 710, in urlopen
    chunked=chunked,
  File "/home/airflow/.local/lib/python3.7/site-packages/urllib3/connectionpool.py", line 398, in _make_request
    conn.request(method, url, **httplib_request_kw)
  File "/home/airflow/.local/lib/python3.7/site-packages/urllib3/connection.py", line 239, in request
    super(HTTPConnection, self).request(method, url, body=body, headers=headers)
  File "/usr/local/lib/python3.7/http/client.py", line 1281, in request
    self._send_request(method, url, body, headers, encode_chunked)
  File "/usr/local/lib/python3.7/http/client.py", line 1327, in _send_request
    self.endheaders(body, encode_chunked=encode_chunked)
  File "/usr/local/lib/python3.7/http/client.py", line 1276, in endheaders
    self._send_output(message_body, encode_chunked=encode_chunked)
  File "/usr/local/lib/python3.7/http/client.py", line 1036, in _send_output
    self.send(msg)
  File "/usr/local/lib/python3.7/http/client.py", line 976, in send
    self.connect()
  File "/home/airflow/.local/lib/python3.7/site-packages/urllib3/connection.py", line 205, in connect
    conn = self._new_conn()
  File "/home/airflow/.local/lib/python3.7/site-packages/urllib3/connection.py", line 187, in _new_conn
    self, "Failed to establish a new connection: %s" % e
urllib3.exceptions.NewConnectionError: <urllib3.connection.HTTPConnection object at 0x785a960c7690>: Failed to establish a new connection: [Errno 111] Connection refused

During handling of the above exception, another exception occurred:

Traceback (most recent call last):
  File "/home/airflow/.local/lib/python3.7/site-packages/requests/adapters.py", line 450, in send
    timeout=timeout
  File "/home/airflow/.local/lib/python3.7/site-packages/urllib3/connectionpool.py", line 786, in urlopen
    method, url, error=e, _pool=self, _stacktrace=sys.exc_info()[2]
  File "/home/airflow/.local/lib/python3.7/site-packages/urllib3/util/retry.py", line 592, in increment
    raise MaxRetryError(_pool, url, error or ResponseError(cause))
urllib3.exceptions.MaxRetryError: HTTPConnectionPool(host='host.docker.internal', port=8000): Max retries exceeded with url: /run-pipeline (Caused by NewConnectionError('<urllib3.connection.HTTPConnection object at 0x785a960c7690>: Failed to establish a new connection: [Errno 111] Connection refused'))

During handling of the above exception, another exception occurred:

Traceback (most recent call last):
  File "/opt/airflow/dags/extract_scheduler.py", line 21, in trigger_pipeline
    response = requests.post(api_url, timeout=30)
  File "/home/airflow/.local/lib/python3.7/site-packages/requests/api.py", line 117, in post
    return request('post', url, data=data, json=json, **kwargs)
  File "/home/airflow/.local/lib/python3.7/site-packages/requests/api.py", line 61, in request
    return session.request(method=method, url=url, **kwargs)
  File "/home/airflow/.local/lib/python3.7/site-packages/requests/sessions.py", line 529, in request
    resp = self.send(prep, **send_kwargs)
  File "/home/airflow/.local/lib/python3.7/site-packages/requests/sessions.py", line 645, in send
    r = adapter.send(request, **kwargs)
  File "/home/airflow/.local/lib/python3.7/site-packages/requests/adapters.py", line 519, in send
    raise ConnectionError(e, request=request)
requests.exceptions.ConnectionError: HTTPConnectionPool(host='host.docker.internal', port=8000): Max retries exceeded with url: /run-pipeline (Caused by NewConnectionError('<urllib3.connection.HTTPConnection object at 0x785a960c7690>: Failed to establish a new connection: [Errno 111] Connection refused'))

During handling of the above exception, another exception occurred:

Traceback (most recent call last):
  File "/home/airflow/.local/lib/python3.7/site-packages/airflow/operators/python.py", line 171, in execute
    return_value = self.execute_callable()
  File "/home/airflow/.local/lib/python3.7/site-packages/airflow/operators/python.py", line 189, in execute_callable
    return self.python_callable(*self.op_args, **self.op_kwargs)
  File "/opt/airflow/dags/extract_scheduler.py", line 45, in trigger_pipeline
    raise Exception(f"API connection error: {str(e)}")
Exception: API connection error: HTTPConnectionPool(host='host.docker.internal', port=8000): Max retries exceeded with url: /run-pipeline (Caused by NewConnectionError('<urllib3.connection.HTTPConnection object at 0x785a960c7690>: Failed to establish a new connection: [Errno 111] Connection refused'))
[2025-05-12 23:37:12,270] {taskinstance.py:1400} INFO - Marking task as UP_FOR_RETRY. dag_id=api_pipeline_integration, task_id=trigger_and_wait_pipeline, execution_date=20250512T232000, start_date=20250512T233712, end_date=20250512T233712
[2025-05-12 23:37:12,275] {standard_task_runner.py:97} ERROR - Failed to execute job 40 for task trigger_and_wait_pipeline (API connection error: HTTPConnectionPool(host='host.docker.internal', port=8000): Max retries exceeded with url: /run-pipeline (Caused by NewConnectionError('<urllib3.connection.HTTPConnection object at 0x785a960c7690>: Failed to establish a new connection: [Errno 111] Connection refused')); 587)
[2025-05-12 23:37:12,311] {local_task_job.py:156} INFO - Task exited with return code 1
[2025-05-12 23:37:12,356] {local_task_job.py:273} INFO - 0 downstream tasks scheduled from follow-on schedule check
[2025-05-12 23:39:25,677] {taskinstance.py:1159} INFO - Dependencies all met for <TaskInstance: api_pipeline_integration.trigger_and_wait_pipeline scheduled__2025-05-12T23:20:00+00:00 [queued]>
[2025-05-12 23:39:25,682] {taskinstance.py:1159} INFO - Dependencies all met for <TaskInstance: api_pipeline_integration.trigger_and_wait_pipeline scheduled__2025-05-12T23:20:00+00:00 [queued]>
[2025-05-12 23:39:25,682] {taskinstance.py:1356} INFO - 
--------------------------------------------------------------------------------
[2025-05-12 23:39:25,682] {taskinstance.py:1357} INFO - Starting attempt 1 of 4
[2025-05-12 23:39:25,682] {taskinstance.py:1358} INFO - 
--------------------------------------------------------------------------------
[2025-05-12 23:39:25,689] {taskinstance.py:1377} INFO - Executing <Task(PythonOperator): trigger_and_wait_pipeline> on 2025-05-12 23:20:00+00:00
[2025-05-12 23:39:25,692] {standard_task_runner.py:52} INFO - Started process 237 to run task
[2025-05-12 23:39:25,694] {standard_task_runner.py:79} INFO - Running: ['***', 'tasks', 'run', 'api_pipeline_integration', 'trigger_and_wait_pipeline', 'scheduled__2025-05-12T23:20:00+00:00', '--job-id', '2', '--raw', '--subdir', 'DAGS_FOLDER/extract_scheduler.py', '--cfg-path', '/tmp/tmphw73_evp', '--error-file', '/tmp/tmpgi5c0str']
[2025-05-12 23:39:25,695] {standard_task_runner.py:80} INFO - Job 2: Subtask trigger_and_wait_pipeline
[2025-05-12 23:39:25,728] {task_command.py:369} INFO - Running <TaskInstance: api_pipeline_integration.trigger_and_wait_pipeline scheduled__2025-05-12T23:20:00+00:00 [running]> on host f4c955ecac73
[2025-05-12 23:39:25,774] {taskinstance.py:1571} INFO - Exporting the following env vars:
AIRFLOW_CTX_DAG_OWNER=***
AIRFLOW_CTX_DAG_ID=api_pipeline_integration
AIRFLOW_CTX_TASK_ID=trigger_and_wait_pipeline
AIRFLOW_CTX_EXECUTION_DATE=2025-05-12T23:20:00+00:00
AIRFLOW_CTX_TRY_NUMBER=1
AIRFLOW_CTX_DAG_RUN_ID=scheduled__2025-05-12T23:20:00+00:00
[2025-05-12 23:39:55,876] {taskinstance.py:1889} ERROR - Task failed with exception
Traceback (most recent call last):
  File "/home/airflow/.local/lib/python3.7/site-packages/urllib3/connection.py", line 175, in _new_conn
    (self._dns_host, self.port), self.timeout, **extra_kw
  File "/home/airflow/.local/lib/python3.7/site-packages/urllib3/util/connection.py", line 95, in create_connection
    raise err
  File "/home/airflow/.local/lib/python3.7/site-packages/urllib3/util/connection.py", line 85, in create_connection
    sock.connect(sa)
socket.timeout: timed out

During handling of the above exception, another exception occurred:

Traceback (most recent call last):
  File "/home/airflow/.local/lib/python3.7/site-packages/urllib3/connectionpool.py", line 710, in urlopen
    chunked=chunked,
  File "/home/airflow/.local/lib/python3.7/site-packages/urllib3/connectionpool.py", line 398, in _make_request
    conn.request(method, url, **httplib_request_kw)
  File "/home/airflow/.local/lib/python3.7/site-packages/urllib3/connection.py", line 239, in request
    super(HTTPConnection, self).request(method, url, body=body, headers=headers)
  File "/usr/local/lib/python3.7/http/client.py", line 1281, in request
    self._send_request(method, url, body, headers, encode_chunked)
  File "/usr/local/lib/python3.7/http/client.py", line 1327, in _send_request
    self.endheaders(body, encode_chunked=encode_chunked)
  File "/usr/local/lib/python3.7/http/client.py", line 1276, in endheaders
    self._send_output(message_body, encode_chunked=encode_chunked)
  File "/usr/local/lib/python3.7/http/client.py", line 1036, in _send_output
    self.send(msg)
  File "/usr/local/lib/python3.7/http/client.py", line 976, in send
    self.connect()
  File "/home/airflow/.local/lib/python3.7/site-packages/urllib3/connection.py", line 205, in connect
    conn = self._new_conn()
  File "/home/airflow/.local/lib/python3.7/site-packages/urllib3/connection.py", line 182, in _new_conn
    % (self.host, self.timeout),
urllib3.exceptions.ConnectTimeoutError: (<urllib3.connection.HTTPConnection object at 0x7999280f2d90>, 'Connection to host.docker.internal timed out. (connect timeout=30)')

During handling of the above exception, another exception occurred:

Traceback (most recent call last):
  File "/home/airflow/.local/lib/python3.7/site-packages/requests/adapters.py", line 450, in send
    timeout=timeout
  File "/home/airflow/.local/lib/python3.7/site-packages/urllib3/connectionpool.py", line 786, in urlopen
    method, url, error=e, _pool=self, _stacktrace=sys.exc_info()[2]
  File "/home/airflow/.local/lib/python3.7/site-packages/urllib3/util/retry.py", line 592, in increment
    raise MaxRetryError(_pool, url, error or ResponseError(cause))
urllib3.exceptions.MaxRetryError: HTTPConnectionPool(host='host.docker.internal', port=8000): Max retries exceeded with url: /run-pipeline (Caused by ConnectTimeoutError(<urllib3.connection.HTTPConnection object at 0x7999280f2d90>, 'Connection to host.docker.internal timed out. (connect timeout=30)'))

During handling of the above exception, another exception occurred:

Traceback (most recent call last):
  File "/opt/airflow/dags/extract_scheduler.py", line 21, in trigger_pipeline
    response = requests.post(api_url, timeout=30)
  File "/home/airflow/.local/lib/python3.7/site-packages/requests/api.py", line 117, in post
    return request('post', url, data=data, json=json, **kwargs)
  File "/home/airflow/.local/lib/python3.7/site-packages/requests/api.py", line 61, in request
    return session.request(method=method, url=url, **kwargs)
  File "/home/airflow/.local/lib/python3.7/site-packages/requests/sessions.py", line 529, in request
    resp = self.send(prep, **send_kwargs)
  File "/home/airflow/.local/lib/python3.7/site-packages/requests/sessions.py", line 645, in send
    r = adapter.send(request, **kwargs)
  File "/home/airflow/.local/lib/python3.7/site-packages/requests/adapters.py", line 507, in send
    raise ConnectTimeout(e, request=request)
requests.exceptions.ConnectTimeout: HTTPConnectionPool(host='host.docker.internal', port=8000): Max retries exceeded with url: /run-pipeline (Caused by ConnectTimeoutError(<urllib3.connection.HTTPConnection object at 0x7999280f2d90>, 'Connection to host.docker.internal timed out. (connect timeout=30)'))

During handling of the above exception, another exception occurred:

Traceback (most recent call last):
  File "/home/airflow/.local/lib/python3.7/site-packages/airflow/operators/python.py", line 171, in execute
    return_value = self.execute_callable()
  File "/home/airflow/.local/lib/python3.7/site-packages/airflow/operators/python.py", line 189, in execute_callable
    return self.python_callable(*self.op_args, **self.op_kwargs)
  File "/opt/airflow/dags/extract_scheduler.py", line 45, in trigger_pipeline
    raise Exception(f"API connection error: {str(e)}")
Exception: API connection error: HTTPConnectionPool(host='host.docker.internal', port=8000): Max retries exceeded with url: /run-pipeline (Caused by ConnectTimeoutError(<urllib3.connection.HTTPConnection object at 0x7999280f2d90>, 'Connection to host.docker.internal timed out. (connect timeout=30)'))
[2025-05-12 23:39:55,892] {taskinstance.py:1400} INFO - Marking task as UP_FOR_RETRY. dag_id=api_pipeline_integration, task_id=trigger_and_wait_pipeline, execution_date=20250512T232000, start_date=20250512T233925, end_date=20250512T233955
[2025-05-12 23:39:55,906] {standard_task_runner.py:97} ERROR - Failed to execute job 2 for task trigger_and_wait_pipeline (API connection error: HTTPConnectionPool(host='host.docker.internal', port=8000): Max retries exceeded with url: /run-pipeline (Caused by ConnectTimeoutError(<urllib3.connection.HTTPConnection object at 0x7999280f2d90>, 'Connection to host.docker.internal timed out. (connect timeout=30)')); 237)
[2025-05-12 23:39:55,925] {local_task_job.py:156} INFO - Task exited with return code 1
[2025-05-12 23:39:55,973] {local_task_job.py:273} INFO - 0 downstream tasks scheduled from follow-on schedule check
