[2025-05-12 23:48:50,883] {taskinstance.py:1159} INFO - Dependencies all met for <TaskInstance: api_pipeline_integration.call_api_endpoint scheduled__2025-05-12T23:20:00+00:00 [queued]>
[2025-05-12 23:48:50,888] {taskinstance.py:1159} INFO - Dependencies all met for <TaskInstance: api_pipeline_integration.call_api_endpoint scheduled__2025-05-12T23:20:00+00:00 [queued]>
[2025-05-12 23:48:50,888] {taskinstance.py:1356} INFO - 
--------------------------------------------------------------------------------
[2025-05-12 23:48:50,888] {taskinstance.py:1357} INFO - Starting attempt 1 of 4
[2025-05-12 23:48:50,888] {taskinstance.py:1358} INFO - 
--------------------------------------------------------------------------------
[2025-05-12 23:48:50,895] {taskinstance.py:1377} INFO - Executing <Task(PythonOperator): call_api_endpoint> on 2025-05-12 23:20:00+00:00
[2025-05-12 23:48:50,899] {standard_task_runner.py:52} INFO - Started process 345 to run task
[2025-05-12 23:48:50,901] {standard_task_runner.py:79} INFO - Running: ['***', 'tasks', 'run', 'api_pipeline_integration', 'call_api_endpoint', 'scheduled__2025-05-12T23:20:00+00:00', '--job-id', '6', '--raw', '--subdir', 'DAGS_FOLDER/extract_scheduler.py', '--cfg-path', '/tmp/tmpr_6t_y3k', '--error-file', '/tmp/tmpkajkiuz4']
[2025-05-12 23:48:50,902] {standard_task_runner.py:80} INFO - Job 6: Subtask call_api_endpoint
[2025-05-12 23:48:50,939] {task_command.py:369} INFO - Running <TaskInstance: api_pipeline_integration.call_api_endpoint scheduled__2025-05-12T23:20:00+00:00 [running]> on host f4c955ecac73
[2025-05-12 23:48:50,985] {taskinstance.py:1571} INFO - Exporting the following env vars:
AIRFLOW_CTX_DAG_OWNER=***
AIRFLOW_CTX_DAG_ID=api_pipeline_integration
AIRFLOW_CTX_TASK_ID=call_api_endpoint
AIRFLOW_CTX_EXECUTION_DATE=2025-05-12T23:20:00+00:00
AIRFLOW_CTX_TRY_NUMBER=1
AIRFLOW_CTX_DAG_RUN_ID=scheduled__2025-05-12T23:20:00+00:00
[2025-05-12 23:49:21,083] {extract_scheduler.py:27} ERROR - API call failed: HTTPConnectionPool(host='host.docker.internal', port=8000): Max retries exceeded with url: /run-pipeline (Caused by ConnectTimeoutError(<urllib3.connection.HTTPConnection object at 0x7999280f9810>, 'Connection to host.docker.internal timed out. (connect timeout=30)'))
[2025-05-12 23:49:21,084] {taskinstance.py:1889} ERROR - Task failed with exception
Traceback (most recent call last):
  File "/home/airflow/.local/lib/python3.7/site-packages/urllib3/connection.py", line 175, in _new_conn
    (self._dns_host, self.port), self.timeout, **extra_kw
  File "/home/airflow/.local/lib/python3.7/site-packages/urllib3/util/connection.py", line 95, in create_connection
    raise err
  File "/home/airflow/.local/lib/python3.7/site-packages/urllib3/util/connection.py", line 85, in create_connection
    sock.connect(sa)
socket.timeout: timed out

During handling of the above exception, another exception occurred:

Traceback (most recent call last):
  File "/home/airflow/.local/lib/python3.7/site-packages/urllib3/connectionpool.py", line 710, in urlopen
    chunked=chunked,
  File "/home/airflow/.local/lib/python3.7/site-packages/urllib3/connectionpool.py", line 398, in _make_request
    conn.request(method, url, **httplib_request_kw)
  File "/home/airflow/.local/lib/python3.7/site-packages/urllib3/connection.py", line 239, in request
    super(HTTPConnection, self).request(method, url, body=body, headers=headers)
  File "/usr/local/lib/python3.7/http/client.py", line 1281, in request
    self._send_request(method, url, body, headers, encode_chunked)
  File "/usr/local/lib/python3.7/http/client.py", line 1327, in _send_request
    self.endheaders(body, encode_chunked=encode_chunked)
  File "/usr/local/lib/python3.7/http/client.py", line 1276, in endheaders
    self._send_output(message_body, encode_chunked=encode_chunked)
  File "/usr/local/lib/python3.7/http/client.py", line 1036, in _send_output
    self.send(msg)
  File "/usr/local/lib/python3.7/http/client.py", line 976, in send
    self.connect()
  File "/home/airflow/.local/lib/python3.7/site-packages/urllib3/connection.py", line 205, in connect
    conn = self._new_conn()
  File "/home/airflow/.local/lib/python3.7/site-packages/urllib3/connection.py", line 182, in _new_conn
    % (self.host, self.timeout),
urllib3.exceptions.ConnectTimeoutError: (<urllib3.connection.HTTPConnection object at 0x7999280f9810>, 'Connection to host.docker.internal timed out. (connect timeout=30)')

During handling of the above exception, another exception occurred:

Traceback (most recent call last):
  File "/home/airflow/.local/lib/python3.7/site-packages/requests/adapters.py", line 450, in send
    timeout=timeout
  File "/home/airflow/.local/lib/python3.7/site-packages/urllib3/connectionpool.py", line 786, in urlopen
    method, url, error=e, _pool=self, _stacktrace=sys.exc_info()[2]
  File "/home/airflow/.local/lib/python3.7/site-packages/urllib3/util/retry.py", line 592, in increment
    raise MaxRetryError(_pool, url, error or ResponseError(cause))
urllib3.exceptions.MaxRetryError: HTTPConnectionPool(host='host.docker.internal', port=8000): Max retries exceeded with url: /run-pipeline (Caused by ConnectTimeoutError(<urllib3.connection.HTTPConnection object at 0x7999280f9810>, 'Connection to host.docker.internal timed out. (connect timeout=30)'))

During handling of the above exception, another exception occurred:

Traceback (most recent call last):
  File "/home/airflow/.local/lib/python3.7/site-packages/airflow/operators/python.py", line 171, in execute
    return_value = self.execute_callable()
  File "/home/airflow/.local/lib/python3.7/site-packages/airflow/operators/python.py", line 189, in execute_callable
    return self.python_callable(*self.op_args, **self.op_kwargs)
  File "/opt/airflow/dags/extract_scheduler.py", line 22, in call_api
    response = requests.post(api_url, timeout=30)
  File "/home/airflow/.local/lib/python3.7/site-packages/requests/api.py", line 117, in post
    return request('post', url, data=data, json=json, **kwargs)
  File "/home/airflow/.local/lib/python3.7/site-packages/requests/api.py", line 61, in request
    return session.request(method=method, url=url, **kwargs)
  File "/home/airflow/.local/lib/python3.7/site-packages/requests/sessions.py", line 529, in request
    resp = self.send(prep, **send_kwargs)
  File "/home/airflow/.local/lib/python3.7/site-packages/requests/sessions.py", line 645, in send
    r = adapter.send(request, **kwargs)
  File "/home/airflow/.local/lib/python3.7/site-packages/requests/adapters.py", line 507, in send
    raise ConnectTimeout(e, request=request)
requests.exceptions.ConnectTimeout: HTTPConnectionPool(host='host.docker.internal', port=8000): Max retries exceeded with url: /run-pipeline (Caused by ConnectTimeoutError(<urllib3.connection.HTTPConnection object at 0x7999280f9810>, 'Connection to host.docker.internal timed out. (connect timeout=30)'))
[2025-05-12 23:49:21,101] {taskinstance.py:1400} INFO - Marking task as UP_FOR_RETRY. dag_id=api_pipeline_integration, task_id=call_api_endpoint, execution_date=20250512T232000, start_date=20250512T234850, end_date=20250512T234921
[2025-05-12 23:49:21,110] {standard_task_runner.py:97} ERROR - Failed to execute job 6 for task call_api_endpoint (HTTPConnectionPool(host='host.docker.internal', port=8000): Max retries exceeded with url: /run-pipeline (Caused by ConnectTimeoutError(<urllib3.connection.HTTPConnection object at 0x7999280f9810>, 'Connection to host.docker.internal timed out. (connect timeout=30)')); 345)
[2025-05-12 23:49:21,124] {local_task_job.py:156} INFO - Task exited with return code 1
[2025-05-12 23:49:21,152] {local_task_job.py:273} INFO - 0 downstream tasks scheduled from follow-on schedule check
